<?xml version="1.0"?>
<robot name="mi_robot" xmlns:xacro="http://www.ros.org/wiki/xacro">

  <!-- ========== VARIABLES ========== -->
  <xacro:property name="base_length"  value="0.3"/>  <!--Units: meters-->
  <xacro:property name="base_width"   value="0.2"/>
  <xacro:property name="base_height"  value="0.1"/>

  <xacro:property name="wheel_radius" value="0.05"/>
  <xacro:property name="wheel_width"  value="0.04"/>

  <!-- Base link-->
  <link name="base_link">
    <visual>
      <geometry>
        <box size="${base_length} ${base_width} ${base_height}"/>
      </geometry>
      <material name="blue">
        <color rgba="0 0 1 1"/>
      </material>
    </visual>
    <collision>
      <geometry>
        <box size="${base_length} ${base_width} ${base_height}"/>
      </geometry>
    </collision>
    <inertial>
      <mass value="1.0"/>
      <inertia 
         ixx="${(1/12) * 1.0 * (base_height**2 + base_width**2)}"
         iyy="${(1/12) * 1.0 * (base_length**2 + base_height**2)}"
         izz="${(1/12) * 1.0 * (base_length**2 + base_width**2)}"
         ixy="0" ixz="0" iyz="0"/>
    </inertial>
  </link>

  <!-- Macro wheel: link + joint (with base link) -->
  <xacro:macro name="wheel" params="name x_pos y_pos">

    <link name="${name}_wheel">
      <visual>
        <geometry>
          <cylinder radius="${wheel_radius}" length="${wheel_width}"/>
        </geometry>
        <origin xyz="0 0 0" rpy="1.5708 0 0"/>
        <material name="black">
          <color rgba="0 0 0 1"/>
        </material>
      </visual>
      <collision>
        <geometry>
          <cylinder radius="${wheel_radius}" length="${wheel_width}"/>
        </geometry>
        <origin xyz="0 0 0" rpy="1.5708 0 0"/>
      </collision>
      <inertial>
        <mass value="0.2"/>
        <inertia
            ixx="${(1/12) * 0.2 * (3 * wheel_radius**2 + wheel_width**2)}"
            iyy="${(1/12) * 0.2 * (3 * wheel_radius**2 + wheel_width**2)}"
            izz="${(1/2)  * 0.2 * wheel_radius**2}"
            ixy="0" ixz="0" iyz="0"/>
      </inertial>
    </link>

    <joint name="${name}_joint" type="continuous">
      <parent link="base_link"/>
      <child  link="${name}_wheel"/>
      <origin xyz="${x_pos} ${y_pos} 0" rpy="0 0 0"/>
      <axis xyz="0 1 0"/>
    </joint>

  </xacro:macro>

  <!-- ========== INSTANCIAR RUEDAS ========== -->
  <!--                        name           x_pos               y_pos -->
  <xacro:wheel name="front_left"  x_pos=" 0.1"  y_pos=" 0.12"/>
  <xacro:wheel name="rear_left"   x_pos="-0.1"  y_pos=" 0.12"/>
  <xacro:wheel name="front_right" x_pos=" 0.1"  y_pos="-0.12"/>
  <xacro:wheel name="rear_right"  x_pos="-0.1"  y_pos="-0.12"/>

</robot>